Workbook

Sheet Cover
B2: MARKET ENTRY STRATEGY
B3: Cultural Experiences Venture — Financial Model
B4: TAM / SAM / SOM · Revenue Projections · Unit Economics · Sensitivity Analysis
B8: Sheet Index
B10: TAM_SAM_SOM | C10: Total / Serviceable / Obtainable Market sizing
B11: Assumptions | C11: All hardcoded inputs & growth drivers
B12: Revenue_Model | C12: 3-year revenue projections by stream
B13: Unit_Economics | C13: CAC, LTV, margins, contribution analysis
B14: Sensitivity | C14: Two-variable sensitivity & scenario tables
B15: Summary_Dashboard | C15: KPI dashboard & charts
B16: Blue = hardcoded input | Black = formula | Green = cross-sheet link | Yellow bg = key assumption

Sheet TAM_SAM_SOM
B1: TAM / SAM / SOM ANALYSIS — CULTURAL EXPERIENCES VENTURE
B2: All figures in Indian Rupees Crore (₹ Cr). Blue = hardcoded input. Black = formula.
B4: 1. TOTAL ADDRESSABLE MARKET (TAM)
B5: Assumption / Driver | C5: Basis | D5: Low | E5: Base | F5: High
B6: Urban India population (M people) | C6: Census + projections | D6: 480 | E6: 500 | F6: 520
B7: Target demographic % (25-45 yrs, >₹8L pa) | C7: Assumption | D7: 0.1 | E7: 0.12 | F7: 0.14
B8: Target consumers (M people) | C8: Number of peoples | D8: =D6*D7 -> 48 | E8: =E6*E7 -> 60 | F8: =F6*F7 -> 72.8
B9: Annual cultural spend per person (₹) | C9: Primary research proxy | D9: 2000 | E9: 3000 | F9: 4000
B10: TAM (₹ Cr) | C10: consumers * spend / Cr | D10: =D8*D9/100 -> 960 | E10: =E8*E9/100 -> 1800 | F10: =F8*F9/100 -> 2912
B12: 2. SERVICEABLE ADDRESSABLE MARKET (SAM)
B13: Assumption / Driver | C13: Basis | D13: Low | E13: Base | F13: High
B14: Top metros + heritage corridors | C14: Bengaluru, Delhi, Mumbai, Jaipur, Varanasi, Chennai, Pune, Kochi | D14: 8 cities | E14: 8 cities | F14: 10 cities
B15: Reachable consumers as % of TAM consumers | C15: Geographic + income filter | D15: 0.18 | E15: 0.2 | F15: 0.24
B16: SAM consumers (M people) | C16: =D15 -> 0.18 | D16: =D8*D15 -> 8.64 | E16: =E8*E15 -> 12 | F16: =F8*F15 -> 17.472
B17: Annual spend (₹) — SAM segment | C17: Higher disposable income | D17: 2500 | E17: 3000 | F17: 3500
B18: SAM (₹ Cr) | C18: consumers * spend / 100 | D18: =D16*D17/100 -> 216 | E18: =E16*E17/100 -> 360 | F18: =F16*F17/100 -> 611.52
B19: SAM CAGR (2026–2030) | C19: Experiential shift + tourism | D19: 0.12 | E19: 0.14 | F19: 0.18
B21: 3. SERVICEABLE OBTAINABLE MARKET (SOM)
B22: Assumption / Driver | C22: Basis | D22: Year 1 | E22: Year 2 | F22: Year 3
B23: Market capture rate (% of SAM) | C23: Comparable D2C cultural brands | D23: 0.001 | E23: 0.003 | F23: 0.005
B24: SOM (₹ Cr) | C24: Base SAM * capture rate | D24: =E18*D23 -> 0.36 | E24: =E18*E23 -> 1.08 | F24: =E18*F23 -> 1.8
B25: SOM as % of SAM | C25: SOM / SAM | D25: =D24/E18 -> 0.001 | E25: =E24/E18 -> 0.003 | F25: =F24/E18 -> 0.005
B27: SUMMARY
B28: Metric | C28: Description | D28: Low | E28: Base | F28: High
B29: TAM (₹ Cr) | C29: Total market opportunity | D29: =D10 -> 960 | E29: =E10 -> 1800 | F29: =F10 -> 2912
B30: SAM (₹ Cr) | C30: Serviceable market | D30: =D18 -> 216 | E30: =E18 -> 360 | F30: =F18 -> 611.52
B31: SOM Year 3 (₹ Cr) | C31: Achievable by Year 3 | D31: =D24 -> 0.36 | E31: =E24 -> 1.08 | F31: =F24 -> 1.8

Sheet Assumptions
B1: KEY ASSUMPTIONS — CULTURAL EXPERIENCES VENTURE
B2: Blue = hardcoded input (change these to run scenarios). Yellow bg = most sensitive assumptions.
B4: A. MACRO & MARKET ASSUMPTIONS
B5: Assumption | C5: Unit | D5: Year 1 | E5: Year 2 | F5: Year 3 | G5: Notes
B6: SAM CAGR | C6: % | D6: 0.14 | E6: 0.14 | F6: 0.14 | G6: Craft experience market growth
B7: Target city count | C7: # cities | D7: 2 | E7: 4 | F7: 6 | G7: Number of flagship studio cities
B8: Heritage tourism growth | C8: %/yr | D8: 0.18 | E8: 0.18 | F8: 0.18 | G8: IRCTC + Airbnb benchmark
B9: Corporate L&D budget CAGR | C9: %/yr | D9: 0.12 | E9: 0.12 | F9: 0.12 | G9: Industry benchmark
B11: B. PRICING ASSUMPTIONS
B12: Assumption | C12: Unit | D12: Year 1 | E12: Year 2 | F12: Year 3 | G12: Notes
B13: Entry workshop avg. ticket (₹) | C13: ₹/session | D13: 1000 | E13: 1050 | F13: 1100 | G13: Drop-in pottery/block print
B14: Mid experience avg. ticket (₹) | C14: ₹/session | D14: 4500 | E14: 4800 | F14: 5000 | G14: Curated 3-hr session
B15: Premium heritage package (₹) | C15: ₹/package | D15: 25000 | E15: 28000 | F15: 32000 | G15: Multi-day immersion
B16: Corporate event avg. (₹) | C16: ₹/event | D16: 150000 | E16: 175000 | F16: 200000 | G16: 50-person offsite
B17: Online subscription MRP (₹/mo) | C17: ₹/mo | D17: 499 | E17: 549 | F17: 599 | G17: Annual plan = 10mo equiv.
B18: Craft kit avg. order (₹) | C18: ₹/order | D18: 1800 | E18: 1900 | F18: 2000 | G18: DIY subscription box
B19: Merchandise / décor AOV (₹) | C19: ₹/order | D19: 3500 | E19: 4000 | F19: 4500 | G19: Artist-led items
B21: C. VOLUME ASSUMPTIONS
B22: Assumption | C22: Unit | D22: Year 1 | E22: Year 2 | F22: Year 3 | G22: Notes
B23: Flagship studios open | C23: # | D23: 2 | E23: 4 | F23: 6 | G23: Cities: BLR, DEL → MUM, JAI
B24: Avg sessions/studio/week | C24: # | D24: 12 | E24: 15 | F24: 18 | G24: Mix of formats
B25: Avg capacity utilisation | C25: % | D25: 0.6 | E25: 0.7 | F25: 0.78 | G25: Ramp-up in Y1
B26: Pax per session (avg) | C26: # | D26: 8 | E26: 9 | F26: 10 | G26: Studio capacity ~15
B27: Corporate events per year | C27: # | D27: 60 | E27: 200 | F27: 400 | G27: B2B direct sales
B28: Online subscribers (end of year) | C28: # | D28: 500 | E28: 2500 | F28: 8000 | G28: Organic + influencer
B29: Craft kit orders/month | C29: # | D29: 200 | E29: 1200 | F29: 4000 | G29: D2C subscription
B30: Merchandise orders/month | C30: # | D30: 150 | E30: 600 | F30: 1800 | G30: Online store + studios
B32: D. COST ASSUMPTIONS
B33: Assumption | C33: Unit | D33: Year 1 | E33: Year 2 | F33: Year 3 | G33: Notes
B34: Studio rent (₹ Cr/yr per studio) | C34: ₹ Cr/yr | D34: 0.3 | E34: 0.32 | F34: 0.34 | G34: Metro premium locations
B35: Artisan revenue share | C35: % | D35: 0.25 | E35: 0.25 | F35: 0.25 | G35: Of experience revenue
B36: Staff cost (₹ Cr/yr per studio) | C36: ₹ Cr/yr | D36: 0.45 | E36: 0.5 | F36: 0.55 | G36: Facilitators + admin
B37: Marketing spend (% of revenue) | C37: % | D37: 0.18 | E37: 0.15 | F37: 0.12 | G37: Reducing as brand builds
B38: COGS — Experiences (% of rev) | C38: % | D38: 0.35 | E38: 0.33 | F38: 0.3 | G38: Materials + artisan share
B39: COGS — Craft kits (% of rev) | C39: % | D39: 0.55 | E39: 0.52 | F39: 0.5 | G39: Sourcing + packaging + shipping
B40: COGS — Online learning (% of rev) | C40: % | D40: 0.25 | E40: 0.22 | F40: 0.2 | G40: Platform + content costs
B41: COGS — Merchandise (% of rev) | C41: % | D41: 0.45 | E41: 0.43 | F41: 0.42 | G41: Artisan goods + fulfilment
B42: Fixed opex ex-rent/staff (₹ Cr/yr) | C42: ₹ Cr/yr | D42: 0.8 | E42: 1.2 | F42: 1.8 | G42: Tech, legal, admin, insurance
B44: E. UNIT ECONOMICS ASSUMPTIONS
B45: Assumption | C45: Unit | D45: Year 1 | E45: Year 2 | F45: Year 3 | G45: Notes
...

Sheet Revenue_Model
B1: REVENUE MODEL — 3-YEAR PROJECTIONS (₹ Crore)
B2: All revenue in ₹ Crore. Formulas pull from Assumptions sheet. Green = cross-sheet link. Black = formula.
B4: Revenue Stream | C4: Driver | D4: Year 1 | E4: Year 2 | F4: Year 3 | G4: 3-Yr CAGR
B6: 1. WORKSHOP & EXPERIENCE REVENUE
B7: Entry workshop attendees/yr | C7: Studios × sessions/wk × 52 × util × pax × 40% mix | D7: =Assumptions!D23*Assumptions!D24*52*Assumptions!D25*Assumptions!D26*0.4 -> 2396.16 | E7: =Assumptions!E23*Assumptions!E24*52*Assumptions!E25*Assumptions!E26*0.4 -> 7862.4 | F7: =Assumptions!F23*Assumptions!F24*52*Assumptions!F25*Assumptions!F26*0.4 -> 17521.92
B8: Entry workshop revenue (₹ Cr) | C8: Attendees × avg ticket / Cr | D8: =D7*Assumptions!D13/10000000 -> 0.239616 | E8: =E7*Assumptions!E13/10000000 -> 0.825552 | F8: =F7*Assumptions!F13/10000000 -> 1.9274112 | G8: =(F8/D8)^(1/2)-1 -> 1.8361506
B9: Mid experience attendees/yr | C9: Studios × sessions/wk × 52 × util × pax × 45% mix | D9: =Assumptions!D23*Assumptions!D24*52*Assumptions!D25*Assumptions!D26*0.45 -> 2695.68 | E9: =Assumptions!E23*Assumptions!E24*52*Assumptions!E25*Assumptions!E26*0.45 -> 8845.2 | F9: =Assumptions!F23*Assumptions!F24*52*Assumptions!F25*Assumptions!F26*0.45 -> 19712.16
B10: Mid experience revenue (₹ Cr) | C10: Attendees × avg ticket / Cr | D10: =D9*Assumptions!D14/10000000 -> 1.213056 | E10: =E9*Assumptions!E14/10000000 -> 4.245696 | F10: =F9*Assumptions!F14/10000000 -> 9.85608 | G10: =(F10/D10)^(1/2)-1 -> 1.8504386
B11: Premium heritage package bookings/yr | C11: Studios × 2 packages/month × 12 | D11: =Assumptions!D23*24 -> 48 | E11: =Assumptions!E23*30 -> 120 | F11: =Assumptions!F23*36 -> 216
B12: Premium heritage revenue (₹ Cr) | C12: Bookings × avg package / Cr | D12: =D11*Assumptions!D15/10000000 -> 0.12 | E12: =E11*Assumptions!E15/10000000 -> 0.336 | F12: =F11*Assumptions!F15/10000000 -> 0.6912 | G12: =(F12/D12)^(1/2)-1 -> 1.4
B13: EXPERIENCE REVENUE TOTAL (₹ Cr) | C13: workshop +mid + premium | D13: =D8+D10+D12 -> 1.572672 | E13: =E8+E10+E12 -> 5.407248 | F13: =F8+F10+F12 -> 12.474691 | G13: =(F13/D13)^(1/2)-1 -> 1.8164097
B15: 2. CORPORATE B2B REVENUE
B16: Corporate event revenue (₹ Cr) | C16: Events × avg ticket / Cr | D16: =Assumptions!D27*Assumptions!D16/10000000 -> 0.9 | E16: =Assumptions!E27*Assumptions!E16/10000000 -> 3.5 | F16: =Assumptions!F27*Assumptions!F16/10000000 -> 8 | G16: =(F16/D16)^(1/2)-1 -> 1.981424
B18: 3. ONLINE LEARNING REVENUE
B19: Online subscription revenue (₹ Cr) | C19: Avg active subs × MRP × 12 / Cr (avg = end/1.5) | D19: =(Assumptions!D28/1.5)*Assumptions!D17*12/10000000 -> 0.1996 | E19: =(Assumptions!E28/1.5)*Assumptions!E17*12/10000000 -> 1.098 | F19: =(Assumptions!F28/1.5)*Assumptions!F17*12/10000000 -> 3.8336 | G19: =(F19/D19)^(1/2)-1 -> 3.3825122
B21: 4. CRAFT KIT (D2C) REVENUE
B22: Craft kit revenue (₹ Cr) | C22: Monthly orders × 12 × AOV / Cr | D22: =Assumptions!D29*12*Assumptions!D18/10000000 -> 0.432 | E22: =Assumptions!E29*12*Assumptions!E18/10000000 -> 2.736 | F22: =Assumptions!F29*12*Assumptions!F18/10000000 -> 9.6 | G22: =(F22/D22)^(1/2)-1 -> 3.7140452
B24: 5. MERCHANDISE & PRODUCTS REVENUE
B25: Merchandise revenue (₹ Cr) | C25: Monthly orders × 12 × AOV / Cr | D25: =Assumptions!D30*12*Assumptions!D19/10000000 -> 0.63 | E25: =Assumptions!E30*12*Assumptions!E19/10000000 -> 2.88 | F25: =Assumptions!F30*12*Assumptions!F19/10000000 -> 9.72 | G25: =(F25/D25)^(1/2)-1 -> 2.927922
B27: TOTAL REVENUE SUMMARY
B28: Stream | C28: % Mix (Yr 3) | D28: Year 1 (₹ Cr) | E28: Year 2 (₹ Cr) | F28: Year 3 (₹ Cr) | G28: CAGR
B29: Experience Revenue | C29: =F29/F34 -> 0.28593124 | D29: =D13 -> 1.572672 | E29: =E13 -> 5.407248 | F29: =F13 -> 12.474691 | G29: =(F29/D29)^(1/2)-1 -> 1.8164097
B30: Corporate B2B | C30: =F30/F34 -> 0.18336726 | D30: =D16 -> 0.9 | E30: =E16 -> 3.5 | F30: =F16 -> 8 | G30: =(F30/D30)^(1/2)-1 -> 1.981424
B31: Online Learning | C31: =F31/F34 -> 0.087869589 | D31: =D19 -> 0.1996 | E31: =E19 -> 1.098 | F31: =F19 -> 3.8336 | G31: =(F31/D31)^(1/2)-1 -> 3.3825122
B32: Craft Kits (D2C) | C32: =F32/F34 -> 0.22004071 | D32: =D22 -> 0.432 | E32: =E22 -> 2.736 | F32: =F22 -> 9.6 | G32: =(F32/D32)^(1/2)-1 -> 3.7140452
B33: Merchandise | C33: =F33/F34 -> 0.22279121 | D33: =D25 -> 0.63 | E33: =E25 -> 2.88 | F33: =F25 -> 9.72 | G33: =(F33/D33)^(1/2)-1 -> 2.927922
B34: TOTAL REVENUE | C34: 100% | D34: =SUM(D29:D33) -> 3.734272 | E34: =SUM(E29:E33) -> 15.621248 | F34: =SUM(F29:F33) -> 43.628291 | G34: =(F34/D34)^(1/2)-1 -> 2.4180714
B36: GROSS PROFIT ANALYSIS
B37: Stream | C37: Year 1 (₹ Cr) | D37: Year 2 (₹ Cr) | E37: Year 3 (₹ Cr) | F37: Yr3 Margin
B38: Experience GP | C38: =D13*(1-Assumptions!D38) -> 1.0222368 | D38: =E13*(1-Assumptions!E38) -> 3.6228562 | E38: =F13*(1-Assumptions!F38) -> 8.7322838 | F38: =E38/F13 -> 0.7
B39: Corporate GP | C39: =D16*(1-Assumptions!D38) -> 0.585 | D39: =E16*(1-Assumptions!E38) -> 2.345 | E39: =F16*(1-Assumptions!F38) -> 5.6 | F39: =E39/F16 -> 0.7
B40: Online GP | C40: =D19*(1-Assumptions!D40) -> 0.1497 | D40: =E19*(1-Assumptions!E40) -> 0.85644 | E40: =F19*(1-Assumptions!F40) -> 3.06688 | F40: =E40/F19 -> 0.8
B41: Craft Kit GP | C41: =D22*(1-Assumptions!D39) -> 0.1944 | D41: =E22*(1-Assumptions!E39) -> 1.31328 | E41: =F22*(1-Assumptions!F39) -> 4.8 | F41: =E41/F22 -> 0.5
B42: Merchandise GP | C42: =D25*(1-Assumptions!D41) -> 0.3465 | D42: =E25*(1-Assumptions!E41) -> 1.6416 | E42: =F25*(1-Assumptions!F41) -> 5.6376 | F42: =E42/F25 -> 0.58
B43: TOTAL GROSS PROFIT | D43: =SUM(C38:C42) -> 2.2978368 | E43: =SUM(D38:D42) -> 9.7791762 | F43: =SUM(E38:E42) -> 27.836764
B44: Blended Gross Margin % | D44: =D43/D34 -> 0.61533729 | E44: =E43/E34 -> 0.6260176 | F44: =F43/F34 -> 0.63804387
B46: OPERATING EXPENSES (₹ Cr)
B47: Expense | C47: Year 1 | D47: Year 2 | E47: Year 3 | F47: % Rev Y3
B48: Studio rent | C48: =Assumptions!D34*Assumptions!D23 -> 0.6 | D48: =Assumptions!E34*Assumptions!E23 -> 1.28 | E48: =Assumptions!F34*Assumptions!F23 -> 2.04 | F48: =E48/F34 -> 0.04675865
B49: Staff cost | C49: =Assumptions!D36*Assumptions!D23 -> 0.9 | D49: =Assumptions!E36*Assumptions!E23 -> 2 | E49: =Assumptions!F36*Assumptions!F23 -> 3.3 | F49: =E49/F34 -> 0.075638993
...

Sheet Unit_Economics
B1: UNIT ECONOMICS — CULTURAL EXPERIENCES VENTURE
B2: Green = links from Assumptions. Black = formulas. All ₹ values.
B4: A. B2C CUSTOMER ECONOMICS
B5: Metric | C5: Formula / Basis | D5: Year 1 | E5: Year 2 | F5: Year 3
B6: CAC — B2C (₹) | C6: From Assumptions | D6: =Assumptions!D46 -> 1200 | E6: =Assumptions!E46 -> 1000 | F6: =Assumptions!F46 -> 900
B7: Average first-order value (₹) | C7: Blended entry + mid ticket | D7: =(Assumptions!D13*0.4+Assumptions!D14*0.6) -> 3100 | E7: =(Assumptions!E13*0.4+Assumptions!E14*0.6) -> 3300 | F7: =(Assumptions!F13*0.4+Assumptions!F14*0.6) -> 3440
B8: Annual repeat revenue per customer (₹) | C8: AOV × repeat rate × 2 visits | D8: =D7*Assumptions!D49*2 -> 2170 | E8: =E7*Assumptions!E49*2 -> 2772 | F8: =F7*Assumptions!F49*2 -> 3440
B9: Online sub revenue per user/yr (₹) | C9: MRP × 12 | D9: =Assumptions!D17*12 -> 5988 | E9: =Assumptions!E17*12 -> 6588 | F9: =Assumptions!F17*12 -> 7188
B10: Estimated LTV (₹) | C10: AOV + repeat rev × LTV months/12 + online sub | D10: =D7+(D8*Assumptions!D48/12)+D9 -> 13428 | E10: =E7+(E8*Assumptions!E48/12)+E9 -> 16356 | F10: =F7+(F8*Assumptions!F48/12)+F9 -> 19801.333
B11: LTV : CAC Ratio | C11: LTV / CAC | D11: =D10/D6 -> 11.19 | E11: =E10/E6 -> 16.356 | F11: =F10/F6 -> 22.001481
B12: CAC Payback (months) | C12: CAC / (AOV gross margin / 12) | D12: =D6/((D7*(1-Assumptions!D38))/12) -> 7.146402 | E12: =E6/((E7*(1-Assumptions!E38))/12) -> 5.4274084 | F12: =F6/((F7*(1-Assumptions!F38))/12) -> 4.4850498
B14: B. B2B CUSTOMER ECONOMICS
B15: Metric | C15: Formula / Basis | D15: Year 1 | E15: Year 2 | F15: Year 3
B16: CAC — B2B (₹) | C16: From Assumptions | D16: =Assumptions!D47 -> 6000 | E16: =Assumptions!E47 -> 5000 | F16: =Assumptions!F47 -> 4000
B17: Annual revenue per B2B client (₹) | C17: Avg events × avg ticket | D17: =Assumptions!D16*2 -> 300000 | E17: =Assumptions!E16*2.5 -> 437500 | F17: =Assumptions!F16*3 -> 600000
B18: Gross profit per B2B client (₹) | C18: Rev × (1 - COGS%) | D18: =D17*(1-Assumptions!D38) -> 195000 | E18: =E17*(1-Assumptions!E38) -> 293125 | F18: =F17*(1-Assumptions!F38) -> 420000
B19: B2B LTV (₹) — 3-yr avg retention | C19: Annual GP × 3 | D19: =D18*3 -> 585000 | E19: =E18*3 -> 879375 | F19: =F18*3 -> 1260000
B20: B2B LTV : CAC Ratio | C20: LTV / CAC | D20: =D19/D16 -> 97.5 | E20: =E19/E16 -> 175.875 | F20: =F19/F16 -> 315
B22: C. CONTRIBUTION MARGIN ANALYSIS
B23: Metric | C23: Formula / Basis | D23: Year 1 | E23: Year 2 | F23: Year 3
B24: Contribution per workshop session (₹) | C24: Ticket × (1 - COGS - artisan share) | D24: =Assumptions!D13*(1-Assumptions!D38-Assumptions!D35) -> 400 | E24: =Assumptions!E13*(1-Assumptions!E38-Assumptions!E35) -> 441 | F24: =Assumptions!F13*(1-Assumptions!F38-Assumptions!F35) -> 495
B25: Contribution per craft kit order (₹) | C25: AOV × (1 - COGS%) | D25: =Assumptions!D18*(1-Assumptions!D39) -> 810 | E25: =Assumptions!E18*(1-Assumptions!E39) -> 912 | F25: =Assumptions!F18*(1-Assumptions!F39) -> 1000
B26: Contribution per online sub/yr (₹) | C26: Sub rev × (1 - COGS%) | D26: =Assumptions!D17*12*(1-Assumptions!D40) -> 4491 | E26: =Assumptions!E17*12*(1-Assumptions!E40) -> 5138.64 | F26: =Assumptions!F17*12*(1-Assumptions!F40) -> 5750.4
B27: Break-even B2C customers needed | C27: Total fixed costs / avg contribution | D27: =(Assumptions!D34*Assumptions!D23+Assumptions!D36*Assumptions!D23+Assumptions!D42)*10000000/(Assumptions!D13*(1-Assumptions!D38-Assumptions!D35)) -> 57500 | E27: =(Assumptions!E34*Assumptions!E23+Assumptions!E36*Assumptions!E23+Assumptions!E42)*10000000/(Assumptions!E13*(1-Assumptions!E38-Assumptions!E35)) -> 101587.3 | F27: =(Assumptions!F34*Assumptions!F23+Assumptions!F36*Assumptions!F23+Assumptions!F42)*10000000/(Assumptions!F13*(1-Assumptions!F38-Assumptions!F35)) -> 144242.42

Sheet Sensitivity
B1: SENSITIVITY & SCENARIO ANALYSIS — CULTURAL EXPERIENCES VENTURE
B2: Two-variable sensitivity tables show Year 3 Total Revenue (₹ Cr) under different assumption combinations.
B4: TABLE 1 — Year 3 Revenue (₹ Cr): Corporate Events/yr × Avg Corporate Ticket (₹)
B5: Events / Ticket → | C5: 100000 | D5: 125000 | E5: 150000 | F5: 175000 | G5: 200000 | H5: 225000 | I5: 250000
B6: 150 | C6: =(150*100000/10000000)+Revenue_Model!F34-Revenue_Model!F16 -> 37.128291 | D6: =(150*125000/10000000)+Revenue_Model!F34-Revenue_Model!F16 -> 37.503291 | E6: =(150*150000/10000000)+Revenue_Model!F34-Revenue_Model!F16 -> 37.878291 | F6: =(150*175000/10000000)+Revenue_Model!F34-Revenue_Model!F16 -> 38.253291 | G6: =(150*200000/10000000)+Revenue_Model!F34-Revenue_Model!F16 -> 38.628291 | H6: =(150*225000/10000000)+Revenue_Model!F34-Revenue_Model!F16 -> 39.003291 | I6: =(150*250000/10000000)+Revenue_Model!F34-Revenue_Model!F16 -> 39.378291
B7: 200 | C7: =(200*100000/10000000)+Revenue_Model!F34-Revenue_Model!F16 -> 37.628291 | D7: =(200*125000/10000000)+Revenue_Model!F34-Revenue_Model!F16 -> 38.128291 | E7: =(200*150000/10000000)+Revenue_Model!F34-Revenue_Model!F16 -> 38.628291 | F7: =(200*175000/10000000)+Revenue_Model!F34-Revenue_Model!F16 -> 39.128291 | G7: =(200*200000/10000000)+Revenue_Model!F34-Revenue_Model!F16 -> 39.628291 | H7: =(200*225000/10000000)+Revenue_Model!F34-Revenue_Model!F16 -> 40.128291 | I7: =(200*250000/10000000)+Revenue_Model!F34-Revenue_Model!F16 -> 40.628291
B8: 250 | C8: =(250*100000/10000000)+Revenue_Model!F34-Revenue_Model!F16 -> 38.128291 | D8: =(250*125000/10000000)+Revenue_Model!F34-Revenue_Model!F16 -> 38.753291 | E8: =(250*150000/10000000)+Revenue_Model!F34-Revenue_Model!F16 -> 39.378291 | F8: =(250*175000/10000000)+Revenue_Model!F34-Revenue_Model!F16 -> 40.003291 | G8: =(250*200000/10000000)+Revenue_Model!F34-Revenue_Model!F16 -> 40.628291 | H8: =(250*225000/10000000)+Revenue_Model!F34-Revenue_Model!F16 -> 41.253291 | I8: =(250*250000/10000000)+Revenue_Model!F34-Revenue_Model!F16 -> 41.878291
B9: 300 | C9: =(300*100000/10000000)+Revenue_Model!F34-Revenue_Model!F16 -> 38.628291 | D9: =(300*125000/10000000)+Revenue_Model!F34-Revenue_Model!F16 -> 39.378291 | E9: =(300*150000/10000000)+Revenue_Model!F34-Revenue_Model!F16 -> 40.128291 | F9: =(300*175000/10000000)+Revenue_Model!F34-Revenue_Model!F16 -> 40.878291 | G9: =(300*200000/10000000)+Revenue_Model!F34-Revenue_Model!F16 -> 41.628291 | H9: =(300*225000/10000000)+Revenue_Model!F34-Revenue_Model!F16 -> 42.378291 | I9: =(300*250000/10000000)+Revenue_Model!F34-Revenue_Model!F16 -> 43.128291
B10: 350 | C10: =(350*100000/10000000)+Revenue_Model!F34-Revenue_Model!F16 -> 39.128291 | D10: =(350*125000/10000000)+Revenue_Model!F34-Revenue_Model!F16 -> 40.003291 | E10: =(350*150000/10000000)+Revenue_Model!F34-Revenue_Model!F16 -> 40.878291 | F10: =(350*175000/10000000)+Revenue_Model!F34-Revenue_Model!F16 -> 41.753291 | G10: =(350*200000/10000000)+Revenue_Model!F34-Revenue_Model!F16 -> 42.628291 | H10: =(350*225000/10000000)+Revenue_Model!F34-Revenue_Model!F16 -> 43.503291 | I10: =(350*250000/10000000)+Revenue_Model!F34-Revenue_Model!F16 -> 44.378291
B11: 400 | C11: =(400*100000/10000000)+Revenue_Model!F34-Revenue_Model!F16 -> 39.628291 | D11: =(400*125000/10000000)+Revenue_Model!F34-Revenue_Model!F16 -> 40.628291 | E11: =(400*150000/10000000)+Revenue_Model!F34-Revenue_Model!F16 -> 41.628291 | F11: =(400*175000/10000000)+Revenue_Model!F34-Revenue_Model!F16 -> 42.628291 | G11: =(400*200000/10000000)+Revenue_Model!F34-Revenue_Model!F16 -> 43.628291 | H11: =(400*225000/10000000)+Revenue_Model!F34-Revenue_Model!F16 -> 44.628291 | I11: =(400*250000/10000000)+Revenue_Model!F34-Revenue_Model!F16 -> 45.628291
B12: 500 | C12: =(500*100000/10000000)+Revenue_Model!F34-Revenue_Model!F16 -> 40.628291 | D12: =(500*125000/10000000)+Revenue_Model!F34-Revenue_Model!F16 -> 41.878291 | E12: =(500*150000/10000000)+Revenue_Model!F34-Revenue_Model!F16 -> 43.128291 | F12: =(500*175000/10000000)+Revenue_Model!F34-Revenue_Model!F16 -> 44.378291 | G12: =(500*200000/10000000)+Revenue_Model!F34-Revenue_Model!F16 -> 45.628291 | H12: =(500*225000/10000000)+Revenue_Model!F34-Revenue_Model!F16 -> 46.878291 | I12: =(500*250000/10000000)+Revenue_Model!F34-Revenue_Model!F16 -> 48.128291
B13: 600 | C13: =(600*100000/10000000)+Revenue_Model!F34-Revenue_Model!F16 -> 41.628291 | D13: =(600*125000/10000000)+Revenue_Model!F34-Revenue_Model!F16 -> 43.128291 | E13: =(600*150000/10000000)+Revenue_Model!F34-Revenue_Model!F16 -> 44.628291 | F13: =(600*175000/10000000)+Revenue_Model!F34-Revenue_Model!F16 -> 46.128291 | G13: =(600*200000/10000000)+Revenue_Model!F34-Revenue_Model!F16 -> 47.628291 | H13: =(600*225000/10000000)+Revenue_Model!F34-Revenue_Model!F16 -> 49.128291 | I13: =(600*250000/10000000)+Revenue_Model!F34-Revenue_Model!F16 -> 50.628291
B14: ★ Yellow = base case (400 events × ₹2,00,000 ticket)
B17: TABLE 2 — Year 3 Online Learning Revenue (₹ Cr): End-of-Year Subs × Monthly Churn
B18: Subs / Churn → | C18: 0.03 | D18: 0.04 | E18: 0.05 | F18: 0.06 | G18: 0.07 | H18: 0.08 | I18: 0.09
B19: 3000 | C19: =(3000/(1+0.03*6))*Assumptions!F17*12/10000000 -> 1.8274576 | D19: =(3000/(1+0.04*6))*Assumptions!F17*12/10000000 -> 1.7390323 | E19: =(3000/(1+0.05*6))*Assumptions!F17*12/10000000 -> 1.6587692 | F19: =(3000/(1+0.06*6))*Assumptions!F17*12/10000000 -> 1.5855882 | G19: =(3000/(1+0.07*6))*Assumptions!F17*12/10000000 -> 1.5185915 | H19: =(3000/(1+0.08*6))*Assumptions!F17*12/10000000 -> 1.457027 | I19: =(3000/(1+0.09*6))*Assumptions!F17*12/10000000 -> 1.4002597
B20: 5000 | C20: =(5000/(1+0.03*6))*Assumptions!F17*12/10000000 -> 3.0457627 | D20: =(5000/(1+0.04*6))*Assumptions!F17*12/10000000 -> 2.8983871 | E20: =(5000/(1+0.05*6))*Assumptions!F17*12/10000000 -> 2.7646154 | F20: =(5000/(1+0.06*6))*Assumptions!F17*12/10000000 -> 2.6426471 | G20: =(5000/(1+0.07*6))*Assumptions!F17*12/10000000 -> 2.5309859 | H20: =(5000/(1+0.08*6))*Assumptions!F17*12/10000000 -> 2.4283784 | I20: =(5000/(1+0.09*6))*Assumptions!F17*12/10000000 -> 2.3337662
B21: 8000 | C21: =(8000/(1+0.03*6))*Assumptions!F17*12/10000000 -> 4.8732203 | D21: =(8000/(1+0.04*6))*Assumptions!F17*12/10000000 -> 4.6374194 | E21: =(8000/(1+0.05*6))*Assumptions!F17*12/10000000 -> 4.4233846 | F21: =(8000/(1+0.06*6))*Assumptions!F17*12/10000000 -> 4.2282353 | G21: =(8000/(1+0.07*6))*Assumptions!F17*12/10000000 -> 4.0495775 | H21: =(8000/(1+0.08*6))*Assumptions!F17*12/10000000 -> 3.8854054 | I21: =(8000/(1+0.09*6))*Assumptions!F17*12/10000000 -> 3.734026
B22: 10000 | C22: =(10000/(1+0.03*6))*Assumptions!F17*12/10000000 -> 6.0915254 | D22: =(10000/(1+0.04*6))*Assumptions!F17*12/10000000 -> 5.7967742 | E22: =(10000/(1+0.05*6))*Assumptions!F17*12/10000000 -> 5.5292308 | F22: =(10000/(1+0.06*6))*Assumptions!F17*12/10000000 -> 5.2852941 | G22: =(10000/(1+0.07*6))*Assumptions!F17*12/10000000 -> 5.0619718 | H22: =(10000/(1+0.08*6))*Assumptions!F17*12/10000000 -> 4.8567568 | I22: =(10000/(1+0.09*6))*Assumptions!F17*12/10000000 -> 4.6675325
B23: 15000 | C23: =(15000/(1+0.03*6))*Assumptions!F17*12/10000000 -> 9.1372881 | D23: =(15000/(1+0.04*6))*Assumptions!F17*12/10000000 -> 8.6951613 | E23: =(15000/(1+0.05*6))*Assumptions!F17*12/10000000 -> 8.2938462 | F23: =(15000/(1+0.06*6))*Assumptions!F17*12/10000000 -> 7.9279412 | G23: =(15000/(1+0.07*6))*Assumptions!F17*12/10000000 -> 7.5929577 | H23: =(15000/(1+0.08*6))*Assumptions!F17*12/10000000 -> 7.2851351 | I23: =(15000/(1+0.09*6))*Assumptions!F17*12/10000000 -> 7.0012987
B24: 20000 | C24: =(20000/(1+0.03*6))*Assumptions!F17*12/10000000 -> 12.183051 | D24: =(20000/(1+0.04*6))*Assumptions!F17*12/10000000 -> 11.593548 | E24: =(20000/(1+0.05*6))*Assumptions!F17*12/10000000 -> 11.058462 | F24: =(20000/(1+0.06*6))*Assumptions!F17*12/10000000 -> 10.570588 | G24: =(20000/(1+0.07*6))*Assumptions!F17*12/10000000 -> 10.123944 | H24: =(20000/(1+0.08*6))*Assumptions!F17*12/10000000 -> 9.7135135 | I24: =(20000/(1+0.09*6))*Assumptions!F17*12/10000000 -> 9.3350649
B25: ★ Yellow = base case (8,000 subs × 5% churn)
B28: TABLE 3 — SCENARIO SUMMARY
B29: Scenario | C29: Key Drivers | D29: Year 1 Rev | E29: Year 2 Rev | F29: Year 3 Rev | G29: EBITDA Y3
B30: Bear Case | C30: Low adoption, 2 studios, high churn | D30: =Revenue_Model!D34*0.7 -> 2.6139904 | E30: =Revenue_Model!E34*0.7 -> 10.934874 | F30: =Revenue_Model!F34*0.7 -> 30.539804 | G30: =Revenue_Model!E53*0.5 -> 7.7306844
B31: Base Case ★ | C31: Assumptions sheet defaults | D31: =Revenue_Model!D34 -> 3.734272 | E31: =Revenue_Model!E34 -> 15.621248 | F31: =Revenue_Model!F34 -> 43.628291 | G31: =Revenue_Model!E53 -> 15.461369
B32: Bull Case | C32: High adoption, 6 studios, low churn | D32: =Revenue_Model!D34*1.4 -> 5.2279808 | E32: =Revenue_Model!E34*1.5 -> 23.431872 | F32: =Revenue_Model!F34*1.6 -> 69.805266 | G32: =Revenue_Model!E53*2 -> 30.922738

Sheet Summary_Dashboard
B1: SUMMARY DASHBOARD — CULTURAL EXPERIENCES VENTURE
B2: All figures in ₹ Crore. Links pull from Revenue_Model and TAM_SAM_SOM sheets.
B4: KEY PERFORMANCE INDICATORS
B5: KPI | C5: Year 1 | D5: Year 2 | E5: Year 3 | F5: Unit
B6: Total Revenue | C6: =Revenue_Model!D34 -> 3.734272 | D6: =Revenue_Model!E34 -> 15.621248 | E6: =Revenue_Model!F34 -> 43.628291 | F6: ₹ Cr
B7: Total Gross Profit | C7: =Revenue_Model!D43 -> 2.2978368 | D7: =Revenue_Model!E43 -> 9.7791762 | E7: =Revenue_Model!F43 -> 27.836764 | F7: ₹ Cr
B8: Blended Gross Margin | C8: =Revenue_Model!D44 -> 0.61533729 | D8: =Revenue_Model!E44 -> 0.6260176 | E8: =Revenue_Model!F44 -> 0.63804387 | F8: %
B9: EBITDA | C9: =Revenue_Model!C53 -> -0.67433216 | D9: =Revenue_Model!D53 -> 2.955989 | E9: =Revenue_Model!E53 -> 15.461369 | F9: ₹ Cr
B10: TAM | C10: =TAM_SAM_SOM!E10 -> 1800 | D10: - | E10: - | F10: ₹ Cr
B11: SAM | C11: =TAM_SAM_SOM!E18 -> 360 | D11: - | E11: - | F11: ₹ Cr
B12: SOM (Year 3) | C12: 2 | D12: =TAM_SAM_SOM!E24 -> 1.08 | E12: =TAM_SAM_SOM!D24 -> 0.36 | F12: ₹ Cr
B14: REVENUE MIX — YEAR 3 (₹ Cr)
B15: Stream | C15: Y1 Rev | D15: Y2 Rev | E15: Y3 Rev | F15: Y3 % | G15: CAGR
B16: Experience Revenue | C16: =Revenue_Model!D13 -> 1.572672 | D16: =Revenue_Model!E13 -> 5.407248 | E16: =Revenue_Model!F13 -> 12.474691 | F16: =E16/E21 -> 0.28593124 | G16: =(E16/C16)^(1/2)-1 -> 1.8164097
B17: Corporate B2B | C17: =Revenue_Model!D16 -> 0.9 | D17: =Revenue_Model!E16 -> 3.5 | E17: =Revenue_Model!F16 -> 8 | F17: =E17/E21 -> 0.18336726 | G17: =(E17/C17)^(1/2)-1 -> 1.981424
B18: Online Learning | C18: =Revenue_Model!D19 -> 0.1996 | D18: =Revenue_Model!E19 -> 1.098 | E18: =Revenue_Model!F19 -> 3.8336 | F18: =E18/E21 -> 0.087869589 | G18: =(E18/C18)^(1/2)-1 -> 3.3825122
B19: Craft Kits | C19: =Revenue_Model!D22 -> 0.432 | D19: =Revenue_Model!E22 -> 2.736 | E19: =Revenue_Model!F22 -> 9.6 | F19: =E19/E21 -> 0.22004071 | G19: =(E19/C19)^(1/2)-1 -> 3.7140452
B20: Merchandise | C20: =Revenue_Model!D25 -> 0.63 | D20: =Revenue_Model!E25 -> 2.88 | E20: =Revenue_Model!F25 -> 9.72 | F20: =E20/E21 -> 0.22279121 | G20: =(E20/C20)^(1/2)-1 -> 2.927922
B21: TOTAL | C21: =SUM(C16:C20) -> 3.734272 | D21: =SUM(D16:D20) -> 15.621248 | E21: =SUM(E16:E20) -> 43.628291
B46: Prepared by : Ankit and Anuj
